<?xml version="1.0" ?>
<!-- =================================================================================== -->
<!-- |    This document was autogenerated by xmacro4sdf from model.sdf.xmacro          | -->
<!-- |    EDITING THIS FILE BY HAND IS NOT RECOMMENDED                                 | -->
<!-- =================================================================================== -->
<sdf version="1.7">
	<!-- include definition -->
	<!--property definition-->
	<!-- scorpio model -->
	<model name="scorpio">
		<pose>0 0 0.2 0 0 0</pose>
		<link name="base_footprint">
			<inertial>
				<mass>1e-09</mass>
				<inertia>
					<ixx>4.000000000000001e-28</ixx>
					<ixy>0</ixy>
					<ixz>0</ixz>
					<iyy>4.000000000000001e-28</iyy>
					<iyz>0</iyz>
					<izz>4.000000000000001e-28</izz>
				</inertia>
			</inertial>
		</link>
		<joint name="base_to_chassis" type="fixed">
			<pose>0 0 0.04 0 0 0</pose>
			<parent>base_footprint</parent>
			<child>base_link</child>
		</joint>
		<link name="base_link">
			<inertial>
				<pose>0.1725 0 0.145 0 0 0</pose>
				<mass>5.0</mass>
				<inertia>
					<ixx>0.032212083333333336</ixx>
					<ixy>0</ixy>
					<ixz>0</ixz>
					<iyy>0.10591208333333335</iyy>
					<iyz>0</iyz>
					<izz>0.10804083333333335</izz>
				</inertia>
			</inertial>
			<visual name="base_visual">
				<pose>0.1575 0 0 0 0 0</pose>
				<geometry>
					<mesh>
						<uri>model://scorpio/meshes/scorpio.stl</uri>
					</mesh>
				</geometry>
				<material>
					<ambient>0.5 0.5 0.5</ambient>
					<diffuse>0.7 0.7 0.7</diffuse>
					<specular>0.9 0.9 0.9</specular>
					<pbr>
						<metal>
							<albedo_map>model://scorpio/meshes/images/base.png</albedo_map>
						</metal>
					</pbr>
				</material>
			</visual>
			<collision name="base_collision">
				<pose>0.1725 0 0.145 0 0 0</pose>
				<geometry>
					<box>
						<size>0.467 0.203 0.19</size>
					</box>
				</geometry>
			</collision>
			<sensor name="base_imu" type="imu">
				<always_on>1</always_on>
				<update_rate>200</update_rate>
			</sensor>
		</link>
		<joint name="rear_left_wheel_joint" type="revolute">
			<pose relative_to="base_link">0.0 0.0928 0.0525 0 0 0</pose>
			<parent>base_link</parent>
			<child>rear_left_wheel</child>
			<axis>
				<xyz>0 1 0</xyz>
				<limit>
					<lower>-1.79769e+308</lower>
					<upper>1.79769e+308</upper>
					<effort>1e+10</effort>
					<velocity>1e+10</velocity>
				</limit>
			</axis>
			<dynamics damping="0.2"/>
		</joint>
		<link name="rear_left_wheel">
			<pose relative_to="rear_left_wheel_joint">0 0 0 0 0 0</pose>
			<inertial>
				<pose>0 0 0 1.5707963267948966 0 0</pose>
				<mass>0.2</mass>
				<inertia>
					<ixx>0.0001724666666666667</ixx>
					<ixy>0</ixy>
					<ixz>0</ixz>
					<iyy>0.0001724666666666667</iyy>
					<iyz>0</iyz>
					<izz>0.0002916</izz>
				</inertia>
			</inertial>
			<visual name="rear_left_wheel_visual">
				<geometry>
					<mesh>
						<uri>model://scorpio/meshes/left_wheel.stl</uri>
					</mesh>
				</geometry>
				<material>
					<ambient>0.1 0.1 0.1</ambient>
					<diffuse>0.05 0.05 0.05</diffuse>
					<specular>0.6 0.6 0.6</specular>
				</material>
			</visual>
			<collision name="rear_left_wheel_collision">
				<pose>0 0 0 1.5707963267948966 0 0</pose>
				<geometry>
					<cylinder>
						<radius>0.054</radius>
						<length>0.04</length>
					</cylinder>
				</geometry>
			</collision>
		</link>
		<joint name="rear_right_wheel_joint" type="revolute">
			<pose relative_to="base_link">0.0 -0.0928 0.0525 0 0 0</pose>
			<parent>base_link</parent>
			<child>rear_right_wheel</child>
			<axis>
				<xyz>0 1 0</xyz>
				<limit>
					<lower>-1.79769e+308</lower>
					<upper>1.79769e+308</upper>
					<effort>1e+10</effort>
					<velocity>1e+10</velocity>
				</limit>
			</axis>
			<dynamics damping="0.2"/>
		</joint>
		<link name="rear_right_wheel">
			<pose relative_to="rear_right_wheel_joint">0 0 0 0 0 0</pose>
			<inertial>
				<pose>0 0 0 1.5707963267948966 0 0</pose>
				<mass>0.2</mass>
				<inertia>
					<ixx>0.0001724666666666667</ixx>
					<ixy>0</ixy>
					<ixz>0</ixz>
					<iyy>0.0001724666666666667</iyy>
					<iyz>0</iyz>
					<izz>0.0002916</izz>
				</inertia>
			</inertial>
			<visual name="rear_right_wheel_visual">
				<geometry>
					<mesh>
						<uri>model://scorpio/meshes/right_wheel.stl</uri>
					</mesh>
				</geometry>
				<material>
					<ambient>0.1 0.1 0.1</ambient>
					<diffuse>0.05 0.05 0.05</diffuse>
					<specular>0.6 0.6 0.6</specular>
				</material>
			</visual>
			<collision name="rear_right_wheel_collision">
				<pose>0 0 0 1.5707963267948966 0 0</pose>
				<geometry>
					<cylinder>
						<radius>0.054</radius>
						<length>0.04</length>
					</cylinder>
				</geometry>
			</collision>
		</link>
		<joint name="front_left_steering_joint" type="revolute">
			<pose relative_to="base_link">0.315 0.0928 0.0525 0 0 0</pose>
			<parent>base_link</parent>
			<child>front_left_steering_link</child>
			<axis>
				<xyz>0 0 1</xyz>
				<limit>
					<lower>-0.5235987755982988</lower>
					<upper>0.5235987755982988</upper>
					<effort>1000</effort>
					<velocity>10</velocity>
				</limit>
			</axis>
			<dynamics damping="0.2"/>
		</joint>
		<link name="front_left_steering_link">
			<pose relative_to="front_left_steering_joint">0 0 0 0 0 0</pose>
			<inertial>
				<mass>1e-09</mass>
				<inertia>
					<ixx>4.000000000000001e-28</ixx>
					<ixy>0</ixy>
					<ixz>0</ixz>
					<iyy>4.000000000000001e-28</iyy>
					<iyz>0</iyz>
					<izz>4.000000000000001e-28</izz>
				</inertia>
			</inertial>
		</link>
		<joint name="front_left_wheel_joint" type="revolute">
			<pose relative_to="front_left_steering_link">0 0 0 0 0 0</pose>
			<parent>front_left_steering_link</parent>
			<child>front_left_wheel</child>
			<axis>
				<xyz>0 1 0</xyz>
				<limit>
					<lower>-1.79769e+308</lower>
					<upper>1.79769e+308</upper>
					<effort>1e+10</effort>
					<velocity>1e+10</velocity>
				</limit>
			</axis>
			<dynamics damping="0.2"/>
		</joint>
		<link name="front_left_wheel">
			<pose relative_to="front_left_wheel_joint">0 0 0 0 0 0</pose>
			<inertial>
				<pose>0 0 0 1.5707963267948966 0 0</pose>
				<mass>0.2</mass>
				<inertia>
					<ixx>0.0001724666666666667</ixx>
					<ixy>0</ixy>
					<ixz>0</ixz>
					<iyy>0.0001724666666666667</iyy>
					<iyz>0</iyz>
					<izz>0.0002916</izz>
				</inertia>
			</inertial>
			<visual name="front_left_wheel_visual">
				<geometry>
					<mesh>
						<uri>model://scorpio/meshes/left_wheel.stl</uri>
					</mesh>
				</geometry>
				<material>
					<ambient>0.1 0.1 0.1</ambient>
					<diffuse>0.05 0.05 0.05</diffuse>
					<specular>0.6 0.6 0.6</specular>
				</material>
			</visual>
			<collision name="front_left_wheel_collision">
				<pose>0 0 0 1.5707963267948966 0 0</pose>
				<geometry>
					<cylinder>
						<radius>0.054</radius>
						<length>0.04</length>
					</cylinder>
				</geometry>
			</collision>
		</link>
		<joint name="front_right_steering_joint" type="revolute">
			<pose relative_to="base_link">0.315 -0.0928 0.0525 0 0 0</pose>
			<parent>base_link</parent>
			<child>front_right_steering_link</child>
			<axis>
				<xyz>0 0 1</xyz>
				<limit>
					<lower>-0.5235987755982988</lower>
					<upper>0.5235987755982988</upper>
					<effort>1000</effort>
					<velocity>10</velocity>
				</limit>
			</axis>
			<dynamics damping="0.2"/>
		</joint>
		<link name="front_right_steering_link">
			<pose relative_to="front_right_steering_joint">0 0 0 0 0 0</pose>
			<inertial>
				<mass>1e-09</mass>
				<inertia>
					<ixx>4.000000000000001e-28</ixx>
					<ixy>0</ixy>
					<ixz>0</ixz>
					<iyy>4.000000000000001e-28</iyy>
					<iyz>0</iyz>
					<izz>4.000000000000001e-28</izz>
				</inertia>
			</inertial>
		</link>
		<joint name="front_right_wheel_joint" type="revolute">
			<pose relative_to="front_right_steering_link">0 0 0 0 0 0</pose>
			<parent>front_right_steering_link</parent>
			<child>front_right_wheel</child>
			<axis>
				<xyz>0 1 0</xyz>
				<limit>
					<lower>-1.79769e+308</lower>
					<upper>1.79769e+308</upper>
					<effort>1e+10</effort>
					<velocity>1e+10</velocity>
				</limit>
			</axis>
			<dynamics damping="0.2"/>
		</joint>
		<link name="front_right_wheel">
			<pose relative_to="front_right_wheel_joint">0 0 0 0 0 0</pose>
			<inertial>
				<pose>0 0 0 1.5707963267948966 0 0</pose>
				<mass>0.2</mass>
				<inertia>
					<ixx>0.0001724666666666667</ixx>
					<ixy>0</ixy>
					<ixz>0</ixz>
					<iyy>0.0001724666666666667</iyy>
					<iyz>0</iyz>
					<izz>0.0002916</izz>
				</inertia>
			</inertial>
			<visual name="front_right_wheel_visual">
				<geometry>
					<mesh>
						<uri>model://scorpio/meshes/right_wheel.stl</uri>
					</mesh>
				</geometry>
				<material>
					<ambient>0.1 0.1 0.1</ambient>
					<diffuse>0.05 0.05 0.05</diffuse>
					<specular>0.6 0.6 0.6</specular>
				</material>
			</visual>
			<collision name="front_right_wheel_collision">
				<pose>0 0 0 1.5707963267948966 0 0</pose>
				<geometry>
					<cylinder>
						<radius>0.054</radius>
						<length>0.04</length>
					</cylinder>
				</geometry>
			</collision>
		</link>
		<plugin filename="ignition-gazebo-joint-state-publisher-system" name="ignition::gazebo::systems::JointStatePublisher">
    </plugin>
		<plugin filename="ignition-gazebo-ackermann-steering-system" name="ignition::gazebo::systems::AckermannSteering">
			<left_joint>front_left_wheel_joint</left_joint>
			<left_joint>rear_left_wheel_joint</left_joint>
			<right_joint>front_right_wheel_joint</right_joint>
			<right_joint>rear_right_wheel_joint</right_joint>
			<left_steering_joint>front_left_steering_joint</left_steering_joint>
			<right_steering_joint>front_right_steering_joint</right_steering_joint>
			<wheel_separation>0.1856</wheel_separation>
			<kingpin_width>0.1856</kingpin_width>
			<wheel_base>0.315</wheel_base>
			<wheel_radius>0.052</wheel_radius>
			<steering_limit>0.7853981633974483</steering_limit>
			<min_velocity>-2.0</min_velocity>
			<max_velocity>2.0</max_velocity>
			<min_acceleration>-6.0</min_acceleration>
			<max_acceleration>6.0</max_acceleration>
			<frame_id>odom</frame_id>
			<child_frame_id>base_link</child_frame_id>
			<odom_publish_frequency>20</odom_publish_frequency>
		</plugin>
	</model>
</sdf>
